Workbook

Sheet Start Here
A1: START HERE — Home Inventory for Insurance & Personal Records
A3: This sheet helps you list the belongings worth recording, room by room — so you can search it, total it, and hand it over when it matters.
A4: This product is a personal property record organizer. It is not insurance advice; it does not promise that any insurer will accept or pay a claim; estimated values are your own figures and have no professional appraisal effect. Whether something is covered, and for how much, is between you and your insurer.
A6: MAKE YOUR OWN COPY (GOOGLE SHEETS)
A7: 1. Use the ready-made copy link provided with your download. It opens this sheet with the copy button ready.
A8: 2. Click "Make a copy". Google saves the copy into your own Drive, under your own account.
A9: 3. Rename it if you like, then open the Inventory tab and start with the light-blue cells.
A11: Opened this sheet from Google Drive instead of the link? Go to File > Make a copy — same result.
A13: THEN, THE 30-SECOND START
A14: On the Inventory tab: pick a room, type the item, how many, what it is worth, and where it is. That is all you ever type — totals, room summaries and the handover page work themselves out.
A16: ONLY RECORD WHAT IS WORTH RECORDING
A17: Do not list every spoon. Record the things you would need to describe if they were lost, damaged or handed over — valuable items, electronics, appliances, jewelry, tools. A short list you actually finish beats a full-house list you abandon.
... A42: Personal use only. Settled Days

Sheet Inventory
A1: Room | B1: Item | C1: Qty | D1: Category | E1: Purchase date | F1: Purchase price | G1: Estimated value | H1: Serial number | I1: Location (in room) | J1: Belongs to | K1: Notes | L1: Photo filename / link | M1: Attention
A2: Living Room | B2: 55-inch television | C2: 1 | D2: Electronics | E2: 44270 | F2: 700 | G2: 500 | H2: EXAMPLE-SN-001 | I2: On TV stand | J2: Me | L2: EXAMPLE-photo-01.jpg | M2: =IF(OR($G2="",Summary!$B$2=""),"",IF($G2>=Summary!$B$2,"★ Attention",""))
A3: Living Room | B3: Three-seat sofa | C3: 1 | D3: Furniture | E3: 43983 | F3: 900 | G3: 600 | I3: Against north wall | J3: Me | M3: =IF(OR($G3="",Summary!$B$2=""),"",IF($G3>=Summary!$B$2,"★ Attention",""))
A4: Living Room | B4: Soundbar | C4: 1 | D4: Electronics | E4: 44885 | F4: 200 | G4: 120 | I4: Under TV | J4: Me | L4: EXAMPLE-photo-02.jpg | M4: =IF(OR($G4="",Summary!$B$2=""),"",IF($G4>=Summary!$B$2,"★ Attention",""))
A5: Living Room | B5: Floor lamp | C5: 2 | D5: Furniture | E5: 43687 | F5: 120 | G5: 60 | I5: Corners | J5: Me | M5: =IF(OR($G5="",Summary!$B$2=""),"",IF($G5>=Summary!$B$2,"★ Attention",""))
A6: Kitchen | B6: Refrigerator | C6: 1 | D6: Appliances | E6: 43842 | F6: 1100 | G6: 800 | H6: EXAMPLE-SN-002 | I6: Kitchen | J6: Me | L6: EXAMPLE-photo-03.jpg | M6: =IF(OR($G6="",Summary!$B$2=""),"",IF($G6>=Summary!$B$2,"★ Attention",""))
A7: Kitchen | B7: Stand mixer | C7: 1 | D7: Appliances | E7: 44711 | F7: 300 | G7: 200 | I7: Countertop | J7: Me | M7: =IF(OR($G7="",Summary!$B$2=""),"",IF($G7>=Summary!$B$2,"★ Attention",""))
A8: Kitchen | B8: Knife set | C8: 1 | D8: Kitchenware | E8: 44535 | F8: 150 | G8: 90 | I8: Drawer | J8: Me | M8: =IF(OR($G8="",Summary!$B$2=""),"",IF($G8>=Summary!$B$2,"★ Attention",""))
A9: Kitchen | B9: Coffee machine | C9: 1 | D9: Appliances | E9: 44971 | F9: 180 | G9: 120 | I9: Countertop | J9: Me | L9: EXAMPLE-photo-04.jpg | M9: =IF(OR($G9="",Summary!$B$2=""),"",IF($G9>=Summary!$B$2,"★ Attention",""))
A10: Bedroom (Primary) | B10: Queen bed frame | C10: 1 | D10: Furniture | E10: 43983 | F10: 600 | G10: 400 | I10: Bedroom | J10: Me | M10: =IF(OR($G10="",Summary!$B$2=""),"",IF($G10>=Summary!$B$2,"★ Attention",""))
A11: Bedroom (Primary) | B11: Mattress | C11: 1 | D11: Furniture | E11: 43983 | F11: 800 | G11: 500 | I11: Bedroom | J11: Me | M11: =IF(OR($G11="",Summary!$B$2=""),"",IF($G11>=Summary!$B$2,"★ Attention",""))
A12: Bedroom (Primary) | B12: Wristwatch | C12: 1 | D12: Jewelry & Watches | E12: 43824 | F12: 1500 | G12: 1200 | H12: EXAMPLE-SN-003 | I12: Dresser drawer | J12: Me | K12: Gift | L12: EXAMPLE-photo-05.jpg | M12: =IF(OR($G12="",Summary!$B$2=""),"",IF($G12>=Summary!$B$2,"★ Attention",""))
A13: Bedroom (Guest/Other) | B13: Single bed | C13: 1 | D13: Furniture | E13: 43191 | F13: 300 | G13: 150 | I13: Guest room | J13: Me | M13: =IF(OR($G13="",Summary!$B$2=""),"",IF($G13>=Summary!$B$2,"★ Attention",""))
A14: Bedroom (Guest/Other) | B14: Office chair | C14: 1 | D14: Furniture | E14: 44440 | F14: 130 | G14: 70 | I14: Guest room | J14: Me | M14: =IF(OR($G14="",Summary!$B$2=""),"",IF($G14>=Summary!$B$2,"★ Attention",""))
A15: Bathroom | B15: Hair dryer | C15: 1 | D15: Electronics | E15: 44749 | F15: 60 | G15: 30 | I15: Vanity | J15: Me | M15: =IF(OR($G15="",Summary!$B$2=""),"",IF($G15>=Summary!$B$2,"★ Attention",""))
A16: Home Office / Study | B16: Laptop computer | C16: 1 | D16: Electronics | E16: 45200 | F16: 1300 | G16: 1000 | H16: EXAMPLE-SN-004 | I16: On desk | J16: Me | K16: Work use | L16: EXAMPLE-photo-06.jpg | M16: =IF(OR($G16="",Summary!$B$2=""),"",IF($G16>=Summary!$B$2,"★ Attention",""))
A17: Home Office / Study | B17: Monitor 27-inch | C17: 1 | D17: Electronics | E17: 45200 | F17: 350 | G17: 250 | I17: On desk | J17: Me | M17: =IF(OR($G17="",Summary!$B$2=""),"",IF($G17>=Summary!$B$2,"★ Attention",""))
A18: Home Office / Study | B18: Printer | C18: 1 | D18: Electronics | E18: 44336 | F18: 220 | G18: 120 | H18: EXAMPLE-SN-005 | I18: Shelf | J18: Me | L18: EXAMPLE-photo-07.jpg | M18: =IF(OR($G18="",Summary!$B$2=""),"",IF($G18>=Summary!$B$2,"★ Attention",""))
A19: Home Office / Study | B19: Office chair | C19: 1 | D19: Furniture | E19: 44635 | F19: 280 | G19: 180 | I19: Desk | J19: Me | M19: =IF(OR($G19="",Summary!$B$2=""),"",IF($G19>=Summary!$B$2,"★ Attention",""))
A20: Garage | B20: Tool set | C20: 1 | D20: Tools & Equipment | E20: 43780 | F20: 250 | G20: 150 | I20: Workbench | J20: Me | M20: =IF(OR($G20="",Summary!$B$2=""),"",IF($G20>=Summary!$B$2,"★ Attention",""))
A21: Garage | B21: Lawn mower | C21: 1 | D21: Tools & Equipment | E21: 43939 | F21: 420 | I21: Garage corner | J21: Me | K21: Value unknown | M21: =IF(OR($G21="",Summary!$B$2=""),"",IF($G21>=Summary!$B$2,"★ Attention",""))
A22: Garage | B22: Bicycle | C22: 2 | D22: Sports & Outdoor | E22: 44317 | F22: 600 | G22: 400 | I22: Garage wall | J22: Family | L22: EXAMPLE-photo-08.jpg | M22: =IF(OR($G22="",Summary!$B$2=""),"",IF($G22>=Summary!$B$2,"★ Attention",""))
A23: Basement / Storage | B23: Storage boxes of books | C23: 6 | D23: Other | E23: 42005 | F23: 300 | G23: 100 | I23: Shelves | J23: Me | M23: =IF(OR($G23="",Summary!$B$2=""),"",IF($G23>=Summary!$B$2,"★ Attention",""))
A24: Dining Room | B24: Dining table with a very long descriptive name for testing text wrapping in narrow columns | C24: 1 | D24: Furniture | E24: 43983 | F24: 950 | G24: 650 | I24: Dining room | J24: Me | L24: EXAMPLE-photo-09.jpg | M24: =IF(OR($G24="",Summary!$B$2=""),"",IF($G24>=Summary!$B$2,"★ Attention",""))
A25: Laundry Room | B25: Washing machine | C25: 1 | D25: Appliances | E25: 43524 | F25: 650 | G25: 350 | H25: EXAMPLE-SN-006 | I25: Laundry room | J25: Me | M25: =IF(OR($G25="",Summary!$B$2=""),"",IF($G25>=Summary!$B$2,"★ Attention",""))
A26: Hallway / Entry | B26: Entry console table | C26: 1 | D26: Furniture | E26: 44206 | F26: 180 | G26: 100 | I26: Hallway | J26: Me | M26: =IF(OR($G26="",Summary!$B$2=""),"",IF($G26>=Summary!$B$2,"★ Attention",""))
A27: Home Office / Study | B27: Office chair | C27: 1 | D27: Furniture | F27: 180 | G27: 180 | K27: Boundary: duplicate name | M27: =IF(OR($G27="",Summary!$B$2=""),"",IF($G27>=Summary!$B$2,"★ Attention",""))
A28: Kitchen | B28: Test empty value | C28: 1 | D28: Other | F28: 420 | K28: Boundary: blank value | M28: =IF(OR($G28="",Summary!$B$2=""),"",IF($G28>=Summary!$B$2,"★ Attention",""))
A29: Garage | B29: Test zero value | C29: 1 | D29: Other | F29: 100 | G29: 0 | K29: Boundary: zero value | M29: =IF(OR($G29="",Summary!$B$2=""),"",IF($G29>=Summary!$B$2,"★ Attention",""))
A30: Dining Room | B30: Dining table with a very long descriptive name for wrapping test purposes | C30: 1 | D30: Furniture | F30: 700 | G30: 650 | K30: Boundary: long text | M30: =IF(OR($G30="",Summary!$B$2=""),"",IF($G30>=Summary!$B$2,"★ Attention",""))
A31: Living Room | B31: Test edge 500 | C31: 1 | D31: Other | F31: 500 | G31: 500 | K31: Boundary: value equals attention line | M31: =IF(OR($G31="",Summary!$B$2=""),"",IF($G31>=Summary!$B$2,"★ Attention",""))
M32: =IF(OR($G32="",Summary!$B$2=""),"",IF($G32>=Summary!$B$2,"★ Attention",""))
M33: =IF(OR($G33="",Summary!$B$2=""),"",IF($G33>=Summary!$B$2,"★ Attention",""))
M34: =IF(OR($G34="",Summary!$B$2=""),"",IF($G34>=Summary!$B$2,"★ Attention",""))
M35: =IF(OR($G35="",Summary!$B$2=""),"",IF($G35>=Summary!$B$2,"★ Attention",""))
M36: =IF(OR($G36="",Summary!$B$2=""),"",IF($G36>=Summary!$B$2,"★ Attention",""))
M37: =IF(OR($G37="",Summary!$B$2=""),"",IF($G37>=Summary!$B$2,"★ Attention",""))
M38: =IF(OR($G38="",Summary!$B$2=""),"",IF($G38>=Summary!$B$2,"★ Attention",""))
M39: =IF(OR($G39="",Summary!$B$2=""),"",IF($G39>=Summary!$B$2,"★ Attention",""))
M40: =IF(OR($G40="",Summary!$B$2=""),"",IF($G40>=Summary!$B$2,"★ Attention",""))
...

Sheet Summary
A1: Summary — totals by room
A2: Attention line (you set it): | B2: 500 | C2: Leave blank and nothing is flagged. Type a number, for example 500: items at or above that value are flagged ★ on the Inventory tab and listed below. This line is yours; it is not an insurer limit and promises nothing about insurance.
A4: Room | B4: Items | C4: Total estimated value | D4: Total purchase price
A5: Living Room | B5: =COUNTIF(Inventory!$A$2:$A$201,$A5) | C5: =SUMIFS(Inventory!$G$2:$G$201,Inventory!$A$2:$A$201,$A5) | D5: =SUMIFS(Inventory!$F$2:$F$201,Inventory!$A$2:$A$201,$A5)
A6: Kitchen | B6: =COUNTIF(Inventory!$A$2:$A$201,$A6) | C6: =SUMIFS(Inventory!$G$2:$G$201,Inventory!$A$2:$A$201,$A6) | D6: =SUMIFS(Inventory!$F$2:$F$201,Inventory!$A$2:$A$201,$A6)
A7: Bedroom (Primary) | B7: =COUNTIF(Inventory!$A$2:$A$201,$A7) | C7: =SUMIFS(Inventory!$G$2:$G$201,Inventory!$A$2:$A$201,$A7) | D7: =SUMIFS(Inventory!$F$2:$F$201,Inventory!$A$2:$A$201,$A7)
A8: Bedroom (Guest/Other) | B8: =COUNTIF(Inventory!$A$2:$A$201,$A8) | C8: =SUMIFS(Inventory!$G$2:$G$201,Inventory!$A$2:$A$201,$A8) | D8: =SUMIFS(Inventory!$F$2:$F$201,Inventory!$A$2:$A$201,$A8)
A9: Bathroom | B9: =COUNTIF(Inventory!$A$2:$A$201,$A9) | C9: =SUMIFS(Inventory!$G$2:$G$201,Inventory!$A$2:$A$201,$A9) | D9: =SUMIFS(Inventory!$F$2:$F$201,Inventory!$A$2:$A$201,$A9)
A10: Home Office / Study | B10: =COUNTIF(Inventory!$A$2:$A$201,$A10) | C10: =SUMIFS(Inventory!$G$2:$G$201,Inventory!$A$2:$A$201,$A10) | D10: =SUMIFS(Inventory!$F$2:$F$201,Inventory!$A$2:$A$201,$A10)
A11: Garage | B11: =COUNTIF(Inventory!$A$2:$A$201,$A11) | C11: =SUMIFS(Inventory!$G$2:$G$201,Inventory!$A$2:$A$201,$A11) | D11: =SUMIFS(Inventory!$F$2:$F$201,Inventory!$A$2:$A$201,$A11)
A12: Basement / Storage | B12: =COUNTIF(Inventory!$A$2:$A$201,$A12) | C12: =SUMIFS(Inventory!$G$2:$G$201,Inventory!$A$2:$A$201,$A12) | D12: =SUMIFS(Inventory!$F$2:$F$201,Inventory!$A$2:$A$201,$A12)
A13: Dining Room | B13: =COUNTIF(Inventory!$A$2:$A$201,$A13) | C13: =SUMIFS(Inventory!$G$2:$G$201,Inventory!$A$2:$A$201,$A13) | D13: =SUMIFS(Inventory!$F$2:$F$201,Inventory!$A$2:$A$201,$A13)
A14: Laundry Room | B14: =COUNTIF(Inventory!$A$2:$A$201,$A14) | C14: =SUMIFS(Inventory!$G$2:$G$201,Inventory!$A$2:$A$201,$A14) | D14: =SUMIFS(Inventory!$F$2:$F$201,Inventory!$A$2:$A$201,$A14)
A15: Hallway / Entry | B15: =COUNTIF(Inventory!$A$2:$A$201,$A15) | C15: =SUMIFS(Inventory!$G$2:$G$201,Inventory!$A$2:$A$201,$A15) | D15: =SUMIFS(Inventory!$F$2:$F$201,Inventory!$A$2:$A$201,$A15)
A16: Other | B16: =COUNTIF(Inventory!$A$2:$A$201,$A16) | C16: =SUMIFS(Inventory!$G$2:$G$201,Inventory!$A$2:$A$201,$A16) | D16: =SUMIFS(Inventory!$F$2:$F$201,Inventory!$A$2:$A$201,$A16)
A17: TOTAL | B17: =SUM(B5:B16) | C17: =SUM(C5:C16) | D17: =SUM(D5:D16)
A19: High-value items (at or above your attention line) — live Google Sheet formula (FILTER); verify in Sheets.
A20: =IF($B$2="","",FILTER(Inventory!A2:G201,(Inventory!G2:G201<>"")*(Inventory!G2:G201>=$B$2)))

Sheet Handover
A1: Handover Summary — Home Inventory
A2: Prepared on: | B2: =TODAY()
A3: This page is generated from your Inventory tab. Print it or download it as PDF or Excel (File > Download) to hand over.
A4: This product is a personal property record organizer. It is not insurance advice; it does not promise that any insurer will accept or pay a claim; estimated values are your own figures and have no professional appraisal effect. Whether something is covered, and for how much, is between you and your insurer.
A5: Keep the file in your own Google Drive and export a backup yourself — it does not depend on a seller subscription service. No seller account is needed; using a Google Sheets online copy usually needs a Google account.
A7: Room | B7: Items | C7: Total value
A8: Living Room | B8: =Summary!B5 | C8: =Summary!C5
A9: Kitchen | B9: =Summary!B6 | C9: =Summary!C6
A10: Bedroom (Primary) | B10: =Summary!B7 | C10: =Summary!C7
A11: Bedroom (Guest/Other) | B11: =Summary!B8 | C11: =Summary!C8
A12: Bathroom | B12: =Summary!B9 | C12: =Summary!C9
A13: Home Office / Study | B13: =Summary!B10 | C13: =Summary!C10
A14: Garage | B14: =Summary!B11 | C14: =Summary!C11
A15: Basement / Storage | B15: =Summary!B12 | C15: =Summary!C12
A16: Dining Room | B16: =Summary!B13 | C16: =Summary!C13
A17: Laundry Room | B17: =Summary!B14 | C17: =Summary!C14
A18: Hallway / Entry | B18: =Summary!B15 | C18: =Summary!C15
A19: Other | B19: =Summary!B16 | C19: =Summary!C16
A20: TOTAL | B20: =Summary!B17 | C20: =Summary!C17
A22: Photo list (items with a photo filename or link) — live Google Sheet formula (QUERY); verify in Sheets.
A23: =QUERY(Inventory!A2:L201,"select B, A, L where L is not null and L <> ''",0)

Sheet Lists
A1: Rooms | C1: Categories
A2: Living Room | C2: Electronics
A3: Kitchen | C3: Appliances
A4: Bedroom (Primary) | C4: Furniture
A5: Bedroom (Guest/Other) | C5: Jewelry & Watches
A6: Bathroom | C6: Tools & Equipment
A7: Home Office / Study | C7: Clothing & Accessories
A8: Garage | C8: Kitchenware
A9: Basement / Storage | C9: Sports & Outdoor
A10: Dining Room | C10: Musical Instruments
A11: Laundry Room | C11: Other
A12: Hallway / Entry
A13: Other
