Workbook

Sheet Start Here
A1: START HERE — Monthly Budget Spreadsheet
A3: This is the spreadsheet twin of the Settled Days Monthly Budget Planner (print). Same pages, same order — but every page adds itself up, and the twelve month pages roll into one annual page for you.
A4: FIRST, MAKE YOUR OWN COPY
A6: Google Sheets: use the ready-made copy link in the Start Here PDF from your download, then click "Make a copy". The copy lands in your own Google Drive, fully editable.
A7: Opened this file from Drive instead? File > Make a copy does the same thing.
A8: Excel: the .xlsx file in your download is already yours. If Excel says "Protected View", click "Enable Editing" at the top and start typing.
A9: START WITH THREE PAGES (THE REST IS THERE WHEN YOU NEED IT)
A11: 1. THIS MONTH'S PAGE — open the tab for the current month (Jan, Feb, …). Type your income, your bills and what you spend in the light-blue cells. The grey totals — income, out, saved, left over — add themselves up.
A12: 2. EXPENSE LOG — one line per spend: date, what it was, category, amount. The log totals itself by month and by category at the bottom of the page.
A13: 3. YEAR AT A GLANCE — do not type here at all. It fills itself from the twelve month pages, so you can watch the year build up.
A14: THE OTHER PAGE
A16: DEBT PAYOFF — list each debt once: what you owed at the start, what you have paid so far, the APR and your monthly payment. The sheet works out what is left and an estimated number of months to clear it. Update "Paid so far" as you go.
... A32: Personal use only. Settled Days

Sheet Jan
A1: January — Monthly Budget
A2: Type only in the light-blue cells. The grey totals add themselves up.
A4: INCOME | C4: Planned | D4: Actual
A5: Paycheck 1
A6: Paycheck 2
A7: Other income 1
A8: Other income 2
A9: Total income | C9: =SUM(C5:C8) | D9: =SUM(D5:D8)
A11: FIXED BILLS | B11: Due day | C11: Planned | D11: Actual
A12: Rent / mortgage
A13: Electric
A14: Water
A15: Internet
A16: Phone
A17: Insurance
A18: Car payment
A19: Subscriptions
A22: Total bills | C22: =SUM(C12:C21) | D22: =SUM(D12:D21)
A24: VARIABLE SPENDING | C24: Planned | D24: Actual
A25: Groceries
A26: Dining out
A27: Transport
A28: Home
A29: Shopping
A30: Entertainment
A31: Health & beauty
A32: Personal
A33: Gifts
A34: Other
A35: Total variable spending | C35: =SUM(C25:C34) | D35: =SUM(D25:D34)
A37: SAVINGS GOALS | C37: Planned | D37: Actual
A38: Emergency fund
A39: Vacation
A40: New car
A42: Total savings | C42: =SUM(C38:C41) | D42: =SUM(D38:D41)
A44: MONTH SUMMARY | C44: Planned | D44: Actual
A45: Total income | C45: =C9 | D45: =D9
A46: Total out (bills + spending) | C46: =C22+C35 | D46: =D22+D35
A47: Total saved | C47: =C42 | D47: =D42
A48: Left over | C48: =C45-C46-C47 | D48: =D45-D46-D47
...

Sheet Feb
A1: February — Monthly Budget
A2: Type only in the light-blue cells. The grey totals add themselves up.
A4: INCOME | C4: Planned | D4: Actual
A5: Paycheck 1
A6: Paycheck 2
A7: Other income 1
A8: Other income 2
A9: Total income | C9: =SUM(C5:C8) | D9: =SUM(D5:D8)
A11: FIXED BILLS | B11: Due day | C11: Planned | D11: Actual
A12: Rent / mortgage
A13: Electric
A14: Water
A15: Internet
A16: Phone
A17: Insurance
A18: Car payment
A19: Subscriptions
A22: Total bills | C22: =SUM(C12:C21) | D22: =SUM(D12:D21)
A24: VARIABLE SPENDING | C24: Planned | D24: Actual
A25: Groceries
A26: Dining out
A27: Transport
A28: Home
A29: Shopping
A30: Entertainment
A31: Health & beauty
A32: Personal
A33: Gifts
A34: Other
A35: Total variable spending | C35: =SUM(C25:C34) | D35: =SUM(D25:D34)
A37: SAVINGS GOALS | C37: Planned | D37: Actual
A38: Emergency fund
A39: Vacation
A40: New car
A42: Total savings | C42: =SUM(C38:C41) | D42: =SUM(D38:D41)
A44: MONTH SUMMARY | C44: Planned | D44: Actual
A45: Total income | C45: =C9 | D45: =D9
A46: Total out (bills + spending) | C46: =C22+C35 | D46: =D22+D35
A47: Total saved | C47: =C42 | D47: =D42
A48: Left over | C48: =C45-C46-C47 | D48: =D45-D46-D47
...

Sheet Mar
A1: March — Monthly Budget
A2: Type only in the light-blue cells. The grey totals add themselves up.
A4: INCOME | C4: Planned | D4: Actual
A5: Paycheck 1
A6: Paycheck 2
A7: Other income 1
A8: Other income 2
A9: Total income | C9: =SUM(C5:C8) | D9: =SUM(D5:D8)
A11: FIXED BILLS | B11: Due day | C11: Planned | D11: Actual
A12: Rent / mortgage
A13: Electric
A14: Water
A15: Internet
A16: Phone
A17: Insurance
A18: Car payment
A19: Subscriptions
A22: Total bills | C22: =SUM(C12:C21) | D22: =SUM(D12:D21)
A24: VARIABLE SPENDING | C24: Planned | D24: Actual
A25: Groceries
A26: Dining out
A27: Transport
A28: Home
A29: Shopping
A30: Entertainment
A31: Health & beauty
A32: Personal
A33: Gifts
A34: Other
A35: Total variable spending | C35: =SUM(C25:C34) | D35: =SUM(D25:D34)
A37: SAVINGS GOALS | C37: Planned | D37: Actual
A38: Emergency fund
A39: Vacation
A40: New car
A42: Total savings | C42: =SUM(C38:C41) | D42: =SUM(D38:D41)
A44: MONTH SUMMARY | C44: Planned | D44: Actual
A45: Total income | C45: =C9 | D45: =D9
A46: Total out (bills + spending) | C46: =C22+C35 | D46: =D22+D35
A47: Total saved | C47: =C42 | D47: =D42
A48: Left over | C48: =C45-C46-C47 | D48: =D45-D46-D47
...

Sheet Apr
A1: April — Monthly Budget
A2: Type only in the light-blue cells. The grey totals add themselves up.
A4: INCOME | C4: Planned | D4: Actual
A5: Paycheck 1
A6: Paycheck 2
A7: Other income 1
A8: Other income 2
A9: Total income | C9: =SUM(C5:C8) | D9: =SUM(D5:D8)
A11: FIXED BILLS | B11: Due day | C11: Planned | D11: Actual
A12: Rent / mortgage
A13: Electric
A14: Water
A15: Internet
A16: Phone
A17: Insurance
A18: Car payment
A19: Subscriptions
A22: Total bills | C22: =SUM(C12:C21) | D22: =SUM(D12:D21)
A24: VARIABLE SPENDING | C24: Planned | D24: Actual
A25: Groceries
A26: Dining out
A27: Transport
A28: Home
A29: Shopping
A30: Entertainment
A31: Health & beauty
A32: Personal
A33: Gifts
A34: Other
A35: Total variable spending | C35: =SUM(C25:C34) | D35: =SUM(D25:D34)
A37: SAVINGS GOALS | C37: Planned | D37: Actual
A38: Emergency fund
A39: Vacation
A40: New car
A42: Total savings | C42: =SUM(C38:C41) | D42: =SUM(D38:D41)
A44: MONTH SUMMARY | C44: Planned | D44: Actual
A45: Total income | C45: =C9 | D45: =D9
A46: Total out (bills + spending) | C46: =C22+C35 | D46: =D22+D35
A47: Total saved | C47: =C42 | D47: =D42
A48: Left over | C48: =C45-C46-C47 | D48: =D45-D46-D47
...

Sheet May
A1: May — Monthly Budget
A2: Type only in the light-blue cells. The grey totals add themselves up.
A4: INCOME | C4: Planned | D4: Actual
A5: Paycheck 1
A6: Paycheck 2
A7: Other income 1
A8: Other income 2
A9: Total income | C9: =SUM(C5:C8) | D9: =SUM(D5:D8)
A11: FIXED BILLS | B11: Due day | C11: Planned | D11: Actual
A12: Rent / mortgage
A13: Electric
A14: Water
A15: Internet
A16: Phone
A17: Insurance
A18: Car payment
A19: Subscriptions
A22: Total bills | C22: =SUM(C12:C21) | D22: =SUM(D12:D21)
A24: VARIABLE SPENDING | C24: Planned | D24: Actual
A25: Groceries
A26: Dining out
A27: Transport
A28: Home
A29: Shopping
A30: Entertainment
A31: Health & beauty
A32: Personal
A33: Gifts
A34: Other
A35: Total variable spending | C35: =SUM(C25:C34) | D35: =SUM(D25:D34)
A37: SAVINGS GOALS | C37: Planned | D37: Actual
A38: Emergency fund
A39: Vacation
A40: New car
A42: Total savings | C42: =SUM(C38:C41) | D42: =SUM(D38:D41)
A44: MONTH SUMMARY | C44: Planned | D44: Actual
A45: Total income | C45: =C9 | D45: =D9
A46: Total out (bills + spending) | C46: =C22+C35 | D46: =D22+D35
A47: Total saved | C47: =C42 | D47: =D42
A48: Left over | C48: =C45-C46-C47 | D48: =D45-D46-D47
...

Sheet Jun
A1: June — Monthly Budget
A2: Type only in the light-blue cells. The grey totals add themselves up.
A4: INCOME | C4: Planned | D4: Actual
A5: Paycheck 1
A6: Paycheck 2
A7: Other income 1
A8: Other income 2
A9: Total income | C9: =SUM(C5:C8) | D9: =SUM(D5:D8)
A11: FIXED BILLS | B11: Due day | C11: Planned | D11: Actual
A12: Rent / mortgage
A13: Electric
A14: Water
A15: Internet
A16: Phone
A17: Insurance
A18: Car payment
A19: Subscriptions
A22: Total bills | C22: =SUM(C12:C21) | D22: =SUM(D12:D21)
A24: VARIABLE SPENDING | C24: Planned | D24: Actual
A25: Groceries
A26: Dining out
A27: Transport
A28: Home
A29: Shopping
A30: Entertainment
A31: Health & beauty
A32: Personal
A33: Gifts
A34: Other
A35: Total variable spending | C35: =SUM(C25:C34) | D35: =SUM(D25:D34)
A37: SAVINGS GOALS | C37: Planned | D37: Actual
A38: Emergency fund
A39: Vacation
A40: New car
A42: Total savings | C42: =SUM(C38:C41) | D42: =SUM(D38:D41)
A44: MONTH SUMMARY | C44: Planned | D44: Actual
A45: Total income | C45: =C9 | D45: =D9
A46: Total out (bills + spending) | C46: =C22+C35 | D46: =D22+D35
A47: Total saved | C47: =C42 | D47: =D42
A48: Left over | C48: =C45-C46-C47 | D48: =D45-D46-D47
...

Sheet Jul
A1: July — Monthly Budget
A2: Type only in the light-blue cells. The grey totals add themselves up.
A4: INCOME | C4: Planned | D4: Actual
A5: Paycheck 1
A6: Paycheck 2
A7: Other income 1
A8: Other income 2
A9: Total income | C9: =SUM(C5:C8) | D9: =SUM(D5:D8)
A11: FIXED BILLS | B11: Due day | C11: Planned | D11: Actual
A12: Rent / mortgage
A13: Electric
A14: Water
A15: Internet
A16: Phone
A17: Insurance
A18: Car payment
A19: Subscriptions
A22: Total bills | C22: =SUM(C12:C21) | D22: =SUM(D12:D21)
A24: VARIABLE SPENDING | C24: Planned | D24: Actual
A25: Groceries
A26: Dining out
A27: Transport
A28: Home
A29: Shopping
A30: Entertainment
A31: Health & beauty
A32: Personal
A33: Gifts
A34: Other
A35: Total variable spending | C35: =SUM(C25:C34) | D35: =SUM(D25:D34)
A37: SAVINGS GOALS | C37: Planned | D37: Actual
A38: Emergency fund
A39: Vacation
A40: New car
A42: Total savings | C42: =SUM(C38:C41) | D42: =SUM(D38:D41)
A44: MONTH SUMMARY | C44: Planned | D44: Actual
A45: Total income | C45: =C9 | D45: =D9
A46: Total out (bills + spending) | C46: =C22+C35 | D46: =D22+D35
A47: Total saved | C47: =C42 | D47: =D42
A48: Left over | C48: =C45-C46-C47 | D48: =D45-D46-D47
...

Sheet Aug
A1: August — Monthly Budget
A2: Type only in the light-blue cells. The grey totals add themselves up.
A4: INCOME | C4: Planned | D4: Actual
A5: Paycheck 1
A6: Paycheck 2
A7: Other income 1
A8: Other income 2
A9: Total income | C9: =SUM(C5:C8) | D9: =SUM(D5:D8)
A11: FIXED BILLS | B11: Due day | C11: Planned | D11: Actual
A12: Rent / mortgage
A13: Electric
A14: Water
A15: Internet
A16: Phone
A17: Insurance
A18: Car payment
A19: Subscriptions
A22: Total bills | C22: =SUM(C12:C21) | D22: =SUM(D12:D21)
A24: VARIABLE SPENDING | C24: Planned | D24: Actual
A25: Groceries
A26: Dining out
A27: Transport
A28: Home
A29: Shopping
A30: Entertainment
A31: Health & beauty
A32: Personal
A33: Gifts
A34: Other
A35: Total variable spending | C35: =SUM(C25:C34) | D35: =SUM(D25:D34)
A37: SAVINGS GOALS | C37: Planned | D37: Actual
A38: Emergency fund
A39: Vacation
A40: New car
A42: Total savings | C42: =SUM(C38:C41) | D42: =SUM(D38:D41)
A44: MONTH SUMMARY | C44: Planned | D44: Actual
A45: Total income | C45: =C9 | D45: =D9
A46: Total out (bills + spending) | C46: =C22+C35 | D46: =D22+D35
A47: Total saved | C47: =C42 | D47: =D42
A48: Left over | C48: =C45-C46-C47 | D48: =D45-D46-D47
...

Sheet Sep
A1: September — Monthly Budget
A2: Type only in the light-blue cells. The grey totals add themselves up.
A4: INCOME | C4: Planned | D4: Actual
A5: Paycheck 1
A6: Paycheck 2
A7: Other income 1
A8: Other income 2
A9: Total income | C9: =SUM(C5:C8) | D9: =SUM(D5:D8)
A11: FIXED BILLS | B11: Due day | C11: Planned | D11: Actual
A12: Rent / mortgage
A13: Electric
A14: Water
A15: Internet
A16: Phone
A17: Insurance
A18: Car payment
A19: Subscriptions
A22: Total bills | C22: =SUM(C12:C21) | D22: =SUM(D12:D21)
A24: VARIABLE SPENDING | C24: Planned | D24: Actual
A25: Groceries
A26: Dining out
A27: Transport
A28: Home
A29: Shopping
A30: Entertainment
A31: Health & beauty
A32: Personal
A33: Gifts
A34: Other
A35: Total variable spending | C35: =SUM(C25:C34) | D35: =SUM(D25:D34)
A37: SAVINGS GOALS | C37: Planned | D37: Actual
A38: Emergency fund
A39: Vacation
A40: New car
A42: Total savings | C42: =SUM(C38:C41) | D42: =SUM(D38:D41)
A44: MONTH SUMMARY | C44: Planned | D44: Actual
A45: Total income | C45: =C9 | D45: =D9
A46: Total out (bills + spending) | C46: =C22+C35 | D46: =D22+D35
A47: Total saved | C47: =C42 | D47: =D42
A48: Left over | C48: =C45-C46-C47 | D48: =D45-D46-D47
...

Sheet Oct
A1: October — Monthly Budget
A2: Type only in the light-blue cells. The grey totals add themselves up.
A4: INCOME | C4: Planned | D4: Actual
A5: Paycheck 1
A6: Paycheck 2
A7: Other income 1
A8: Other income 2
A9: Total income | C9: =SUM(C5:C8) | D9: =SUM(D5:D8)
A11: FIXED BILLS | B11: Due day | C11: Planned | D11: Actual
A12: Rent / mortgage
A13: Electric
A14: Water
A15: Internet
A16: Phone
A17: Insurance
A18: Car payment
A19: Subscriptions
A22: Total bills | C22: =SUM(C12:C21) | D22: =SUM(D12:D21)
A24: VARIABLE SPENDING | C24: Planned | D24: Actual
A25: Groceries
A26: Dining out
A27: Transport
A28: Home
A29: Shopping
A30: Entertainment
A31: Health & beauty
A32: Personal
A33: Gifts
A34: Other
A35: Total variable spending | C35: =SUM(C25:C34) | D35: =SUM(D25:D34)
A37: SAVINGS GOALS | C37: Planned | D37: Actual
A38: Emergency fund
A39: Vacation
A40: New car
A42: Total savings | C42: =SUM(C38:C41) | D42: =SUM(D38:D41)
A44: MONTH SUMMARY | C44: Planned | D44: Actual
A45: Total income | C45: =C9 | D45: =D9
A46: Total out (bills + spending) | C46: =C22+C35 | D46: =D22+D35
A47: Total saved | C47: =C42 | D47: =D42
A48: Left over | C48: =C45-C46-C47 | D48: =D45-D46-D47
...

Sheet Nov
A1: November — Monthly Budget
A2: Type only in the light-blue cells. The grey totals add themselves up.
A4: INCOME | C4: Planned | D4: Actual
A5: Paycheck 1
A6: Paycheck 2
A7: Other income 1
A8: Other income 2
A9: Total income | C9: =SUM(C5:C8) | D9: =SUM(D5:D8)
A11: FIXED BILLS | B11: Due day | C11: Planned | D11: Actual
A12: Rent / mortgage
A13: Electric
A14: Water
A15: Internet
A16: Phone
A17: Insurance
A18: Car payment
A19: Subscriptions
A22: Total bills | C22: =SUM(C12:C21) | D22: =SUM(D12:D21)
A24: VARIABLE SPENDING | C24: Planned | D24: Actual
A25: Groceries
A26: Dining out
A27: Transport
A28: Home
A29: Shopping
A30: Entertainment
A31: Health & beauty
A32: Personal
A33: Gifts
A34: Other
A35: Total variable spending | C35: =SUM(C25:C34) | D35: =SUM(D25:D34)
A37: SAVINGS GOALS | C37: Planned | D37: Actual
A38: Emergency fund
A39: Vacation
A40: New car
A42: Total savings | C42: =SUM(C38:C41) | D42: =SUM(D38:D41)
A44: MONTH SUMMARY | C44: Planned | D44: Actual
A45: Total income | C45: =C9 | D45: =D9
A46: Total out (bills + spending) | C46: =C22+C35 | D46: =D22+D35
A47: Total saved | C47: =C42 | D47: =D42
A48: Left over | C48: =C45-C46-C47 | D48: =D45-D46-D47
...

Sheet Dec
A1: December — Monthly Budget
A2: Type only in the light-blue cells. The grey totals add themselves up.
A4: INCOME | C4: Planned | D4: Actual
A5: Paycheck 1
A6: Paycheck 2
A7: Other income 1
A8: Other income 2
A9: Total income | C9: =SUM(C5:C8) | D9: =SUM(D5:D8)
A11: FIXED BILLS | B11: Due day | C11: Planned | D11: Actual
A12: Rent / mortgage
A13: Electric
A14: Water
A15: Internet
A16: Phone
A17: Insurance
A18: Car payment
A19: Subscriptions
A22: Total bills | C22: =SUM(C12:C21) | D22: =SUM(D12:D21)
A24: VARIABLE SPENDING | C24: Planned | D24: Actual
A25: Groceries
A26: Dining out
A27: Transport
A28: Home
A29: Shopping
A30: Entertainment
A31: Health & beauty
A32: Personal
A33: Gifts
A34: Other
A35: Total variable spending | C35: =SUM(C25:C34) | D35: =SUM(D25:D34)
A37: SAVINGS GOALS | C37: Planned | D37: Actual
A38: Emergency fund
A39: Vacation
A40: New car
A42: Total savings | C42: =SUM(C38:C41) | D42: =SUM(D38:D41)
A44: MONTH SUMMARY | C44: Planned | D44: Actual
A45: Total income | C45: =C9 | D45: =D9
A46: Total out (bills + spending) | C46: =C22+C35 | D46: =D22+D35
A47: Total saved | C47: =C42 | D47: =D42
A48: Left over | C48: =C45-C46-C47 | D48: =D45-D46-D47
...

Sheet Expense Log
A1: Expense Log
A2: One line per spend. Type the date, what it was, the category and the amount — the Month column and the totals at the bottom fill themselves.
A4: Date | B4: Item | C4: Category | D4: Amount | E4: Month (auto)
E5: =IF(A5="","",MONTH(A5))
E6: =IF(A6="","",MONTH(A6))
E7: =IF(A7="","",MONTH(A7))
E8: =IF(A8="","",MONTH(A8))
E9: =IF(A9="","",MONTH(A9))
E10: =IF(A10="","",MONTH(A10))
E11: =IF(A11="","",MONTH(A11))
E12: =IF(A12="","",MONTH(A12))
E13: =IF(A13="","",MONTH(A13))
E14: =IF(A14="","",MONTH(A14))
E15: =IF(A15="","",MONTH(A15))
E16: =IF(A16="","",MONTH(A16))
... E104: =IF(A104="","",MONTH(A104))
A106: TOTALS BY MONTH (AUTO — FROM THE LOG ABOVE)
A107: January | D107: =SUMIFS($D$5:$D$104,$E$5:$E$104,1)
A108: February | D108: =SUMIFS($D$5:$D$104,$E$5:$E$104,2)
A109: March | D109: =SUMIFS($D$5:$D$104,$E$5:$E$104,3)
A110: April | D110: =SUMIFS($D$5:$D$104,$E$5:$E$104,4)
A111: May | D111: =SUMIFS($D$5:$D$104,$E$5:$E$104,5)
A112: June | D112: =SUMIFS($D$5:$D$104,$E$5:$E$104,6)
A113: July | D113: =SUMIFS($D$5:$D$104,$E$5:$E$104,7)
A114: August | D114: =SUMIFS($D$5:$D$104,$E$5:$E$104,8)
A115: September | D115: =SUMIFS($D$5:$D$104,$E$5:$E$104,9)
A116: October | D116: =SUMIFS($D$5:$D$104,$E$5:$E$104,10)
A117: November | D117: =SUMIFS($D$5:$D$104,$E$5:$E$104,11)
A118: December | D118: =SUMIFS($D$5:$D$104,$E$5:$E$104,12)
A119: All entries | D119: =SUM(D5:D104)
A121: TOTALS BY CATEGORY (AUTO)
A122: Groceries | D122: =SUMIF($C$5:$C$104,A122,$D$5:$D$104)
A123: Dining out | D123: =SUMIF($C$5:$C$104,A123,$D$5:$D$104)
A124: Transport | D124: =SUMIF($C$5:$C$104,A124,$D$5:$D$104)
A125: Home | D125: =SUMIF($C$5:$C$104,A125,$D$5:$D$104)
A126: Shopping | D126: =SUMIF($C$5:$C$104,A126,$D$5:$D$104)
A127: Entertainment | D127: =SUMIF($C$5:$C$104,A127,$D$5:$D$104)
A128: Health & beauty | D128: =SUMIF($C$5:$C$104,A128,$D$5:$D$104)
A129: Personal | D129: =SUMIF($C$5:$C$104,A129,$D$5:$D$104)
A130: Gifts | D130: =SUMIF($C$5:$C$104,A130,$D$5:$D$104)
...

Sheet Debt Payoff
A1: Debt Payoff Tracker
A2: One row per debt. Type the first five columns; the sheet works out the balance left, your total monthly payment and an estimated time to clear each debt. Update "Paid so far" as you pay. Estimates assume the same payment every month and no new spending on the debt.
A4: Debt | B4: Starting balance | C4: Paid so far | D4: Balance left | E4: APR | F4: Minimum payment | G4: Extra payment | H4: Monthly payment | I4: Est. months to clear | J4: Est. interest left
D5: =IF(B5="","",B5-IF(C5="",0,C5)) | H5: =IF(B5="","",IF(F5="",0,F5)+IF(G5="",0,G5)) | I5: =IF(B5="","",IF(D5<=0,"Paid off",IF(H5<=0,"",IF(IF(E5="",0,E5)=0,ROUNDUP(D5/H5,0),IF(H5<=D5*IF(E5="",0,E5)/12,"Payment too low",ROUNDUP(-LN(1-IF(E5="",0,E5)/12*D5/H5)/LN(1+IF(E5="",0,E5)/12),0)))))) | J5: =IF(ISNUMBER(I5),I5*H5-D5,"")
D6: =IF(B6="","",B6-IF(C6="",0,C6)) | H6: =IF(B6="","",IF(F6="",0,F6)+IF(G6="",0,G6)) | I6: =IF(B6="","",IF(D6<=0,"Paid off",IF(H6<=0,"",IF(IF(E6="",0,E6)=0,ROUNDUP(D6/H6,0),IF(H6<=D6*IF(E6="",0,E6)/12,"Payment too low",ROUNDUP(-LN(1-IF(E6="",0,E6)/12*D6/H6)/LN(1+IF(E6="",0,E6)/12),0)))))) | J6: =IF(ISNUMBER(I6),I6*H6-D6,"")
D7: =IF(B7="","",B7-IF(C7="",0,C7)) | H7: =IF(B7="","",IF(F7="",0,F7)+IF(G7="",0,G7)) | I7: =IF(B7="","",IF(D7<=0,"Paid off",IF(H7<=0,"",IF(IF(E7="",0,E7)=0,ROUNDUP(D7/H7,0),IF(H7<=D7*IF(E7="",0,E7)/12,"Payment too low",ROUNDUP(-LN(1-IF(E7="",0,E7)/12*D7/H7)/LN(1+IF(E7="",0,E7)/12),0)))))) | J7: =IF(ISNUMBER(I7),I7*H7-D7,"")
D8: =IF(B8="","",B8-IF(C8="",0,C8)) | H8: =IF(B8="","",IF(F8="",0,F8)+IF(G8="",0,G8)) | I8: =IF(B8="","",IF(D8<=0,"Paid off",IF(H8<=0,"",IF(IF(E8="",0,E8)=0,ROUNDUP(D8/H8,0),IF(H8<=D8*IF(E8="",0,E8)/12,"Payment too low",ROUNDUP(-LN(1-IF(E8="",0,E8)/12*D8/H8)/LN(1+IF(E8="",0,E8)/12),0)))))) | J8: =IF(ISNUMBER(I8),I8*H8-D8,"")
D9: =IF(B9="","",B9-IF(C9="",0,C9)) | H9: =IF(B9="","",IF(F9="",0,F9)+IF(G9="",0,G9)) | I9: =IF(B9="","",IF(D9<=0,"Paid off",IF(H9<=0,"",IF(IF(E9="",0,E9)=0,ROUNDUP(D9/H9,0),IF(H9<=D9*IF(E9="",0,E9)/12,"Payment too low",ROUNDUP(-LN(1-IF(E9="",0,E9)/12*D9/H9)/LN(1+IF(E9="",0,E9)/12),0)))))) | J9: =IF(ISNUMBER(I9),I9*H9-D9,"")
D10: =IF(B10="","",B10-IF(C10="",0,C10)) | H10: =IF(B10="","",IF(F10="",0,F10)+IF(G10="",0,G10)) | I10: =IF(B10="","",IF(D10<=0,"Paid off",IF(H10<=0,"",IF(IF(E10="",0,E10)=0,ROUNDUP(D10/H10,0),IF(H10<=D10*IF(E10="",0,E10)/12,"Payment too low",ROUNDUP(-LN(1-IF(E10="",0,E10)/12*D10/H10)/LN(1+IF(E10="",0,E10)/12),0)))))) | J10: =IF(ISNUMBER(I10),I10*H10-D10,"")
D11: =IF(B11="","",B11-IF(C11="",0,C11)) | H11: =IF(B11="","",IF(F11="",0,F11)+IF(G11="",0,G11)) | I11: =IF(B11="","",IF(D11<=0,"Paid off",IF(H11<=0,"",IF(IF(E11="",0,E11)=0,ROUNDUP(D11/H11,0),IF(H11<=D11*IF(E11="",0,E11)/12,"Payment too low",ROUNDUP(-LN(1-IF(E11="",0,E11)/12*D11/H11)/LN(1+IF(E11="",0,E11)/12),0)))))) | J11: =IF(ISNUMBER(I11),I11*H11-D11,"")
D12: =IF(B12="","",B12-IF(C12="",0,C12)) | H12: =IF(B12="","",IF(F12="",0,F12)+IF(G12="",0,G12)) | I12: =IF(B12="","",IF(D12<=0,"Paid off",IF(H12<=0,"",IF(IF(E12="",0,E12)=0,ROUNDUP(D12/H12,0),IF(H12<=D12*IF(E12="",0,E12)/12,"Payment too low",ROUNDUP(-LN(1-IF(E12="",0,E12)/12*D12/H12)/LN(1+IF(E12="",0,E12)/12),0)))))) | J12: =IF(ISNUMBER(I12),I12*H12-D12,"")
A13: Totals | B13: =SUM(B5:B12) | C13: =SUM(C5:C12) | D13: =SUM(D5:D12) | H13: =SUM(H5:H12)
A15: Est. months and Est. interest left are estimates: they assume your payment stays the same and the APR does not change. The interest estimate counts the final month as a full payment, so it can read up to one payment higher than the exact figure.

Sheet Year at a Glance
A1: Year at a Glance
A2: This page fills itself from the twelve month pages — there is nothing to type here. It shows Actual figures.
A4: Month | B4: Income | C4: Bills | D4: Variable spending | E4: Savings | F4: Left over
A5: January | B5: ='Jan'!D9 | C5: ='Jan'!D22 | D5: ='Jan'!D35 | E5: ='Jan'!D42 | F5: ='Jan'!D48
A6: February | B6: ='Feb'!D9 | C6: ='Feb'!D22 | D6: ='Feb'!D35 | E6: ='Feb'!D42 | F6: ='Feb'!D48
A7: March | B7: ='Mar'!D9 | C7: ='Mar'!D22 | D7: ='Mar'!D35 | E7: ='Mar'!D42 | F7: ='Mar'!D48
A8: April | B8: ='Apr'!D9 | C8: ='Apr'!D22 | D8: ='Apr'!D35 | E8: ='Apr'!D42 | F8: ='Apr'!D48
A9: May | B9: ='May'!D9 | C9: ='May'!D22 | D9: ='May'!D35 | E9: ='May'!D42 | F9: ='May'!D48
A10: June | B10: ='Jun'!D9 | C10: ='Jun'!D22 | D10: ='Jun'!D35 | E10: ='Jun'!D42 | F10: ='Jun'!D48
A11: July | B11: ='Jul'!D9 | C11: ='Jul'!D22 | D11: ='Jul'!D35 | E11: ='Jul'!D42 | F11: ='Jul'!D48
A12: August | B12: ='Aug'!D9 | C12: ='Aug'!D22 | D12: ='Aug'!D35 | E12: ='Aug'!D42 | F12: ='Aug'!D48
A13: September | B13: ='Sep'!D9 | C13: ='Sep'!D22 | D13: ='Sep'!D35 | E13: ='Sep'!D42 | F13: ='Sep'!D48
A14: October | B14: ='Oct'!D9 | C14: ='Oct'!D22 | D14: ='Oct'!D35 | E14: ='Oct'!D42 | F14: ='Oct'!D48
A15: November | B15: ='Nov'!D9 | C15: ='Nov'!D22 | D15: ='Nov'!D35 | E15: ='Nov'!D42 | F15: ='Nov'!D48
A16: December | B16: ='Dec'!D9 | C16: ='Dec'!D22 | D16: ='Dec'!D35 | E16: ='Dec'!D42 | F16: ='Dec'!D48
A17: Year total | B17: =SUM(B5:B16) | C17: =SUM(C5:C16) | D17: =SUM(D5:D16) | E17: =SUM(E5:E16) | F17: =SUM(F5:F16)
A18: Monthly average | B18: =AVERAGE(B5:B16) | C18: =AVERAGE(C5:C16) | D18: =AVERAGE(D5:D16) | E18: =AVERAGE(E5:E16) | F18: =AVERAGE(F5:F16)
